I tensorflow/stream_executor/dso_loader.cc:108] successfully opened CUDA library libcublas.so.7.5 locally
I tensorflow/stream_executor/dso_loader.cc:108] successfully opened CUDA library libcudnn.so.5 locally
I tensorflow/stream_executor/dso_loader.cc:108] successfully opened CUDA library libcufft.so.7.5 locally
I tensorflow/stream_executor/dso_loader.cc:108] successfully opened CUDA library libcuda.so.1 locally
I tensorflow/stream_executor/dso_loader.cc:108] successfully opened CUDA library libcurand.so.7.5 locally
I tensorflow/core/common_runtime/gpu/gpu_init.cc:102] Found device 0 with properties: 
name: Tesla K40m
major: 3 minor: 5 memoryClockRate (GHz) 0.745
pciBusID 0000:02:00.0
Total memory: 11.17GiB
Free memory: 11.10GiB
W tensorflow/stream_executor/cuda/cuda_driver.cc:572] creating context when one is currently active; existing: 0x7d2b9bc0
I tensorflow/core/common_runtime/gpu/gpu_init.cc:102] Found device 1 with properties: 
name: Tesla K40m
major: 3 minor: 5 memoryClockRate (GHz) 0.745
pciBusID 0000:82:00.0
Total memory: 11.17GiB
Free memory: 11.10GiB
I tensorflow/core/common_runtime/gpu/gpu_init.cc:59] cannot enable peer access from device ordinal 0 to device ordinal 1
I tensorflow/core/common_runtime/gpu/gpu_init.cc:59] cannot enable peer access from device ordinal 1 to device ordinal 0
I tensorflow/core/common_runtime/gpu/gpu_init.cc:126] DMA: 0 1 
I tensorflow/core/common_runtime/gpu/gpu_init.cc:136] 0:   Y N 
I tensorflow/core/common_runtime/gpu/gpu_init.cc:136] 1:   N Y 
I tensorflow/core/common_runtime/gpu/gpu_device.cc:838] Creating TensorFlow device (/gpu:0) -> (device: 0, name: Tesla K40m, pci bus id: 0000:02:00.0)
I tensorflow/core/common_runtime/gpu/gpu_device.cc:838] Creating TensorFlow device (/gpu:1) -> (device: 1, name: Tesla K40m, pci bus id: 0000:82:00.0)
Traceback (most recent call last):
  File "train_model.py", line 556, in <module>
    tf.app.run()
  File "/hpc/sw/python-2.7.11/lib/python2.7/site-packages/tensorflow/python/platform/app.py", line 30, in run
    sys.exit(main(sys.argv))
  File "train_model.py", line 516, in main
    train_siamese()
  File "train_model.py", line 267, in train_siamese
    _ = sess.run([opt_operation], feed_dict={x1: x1_train, x2: x2_train, y: y_train})
  File "/hpc/sw/python-2.7.11/lib/python2.7/site-packages/tensorflow/python/client/session.py", line 710, in run
    run_metadata_ptr)
  File "/hpc/sw/python-2.7.11/lib/python2.7/site-packages/tensorflow/python/client/session.py", line 887, in _run
    % (np_val.shape, subfeed_t.name, str(subfeed_t.get_shape())))
ValueError: Cannot feed value of shape (128,) for Tensor u'y:0', which has shape '(?, 1)'
srun: error: gcn3: task 0: Exited with exit code 1
srun: Terminating job step 2645598.0
